Workbook
Name _Namelist1: 'Daily Sales Summary Report'!$B$6:$B$47
Name _Productname: '[1]DAILY SALES SUMMARY REPORT'!$B$6:$B$39

Sheet Detailed Sales Report
A1: LIVINGSTONE
A3: SALES DETAILS
A5: Invoice Number | B5: DATE | C5: Products (Use Drop Down) | D5: Selling Price (edit prohibited) | E5: Quantities | F5: Discount (Approval required) | G5: Total Paid (Ghs) (edit prohibited)
A6: 1 | D6: =IFERROR(VLOOKUP(C6, 'Daily Sales Summary Report'!$B$6:$C$47, 2, FALSE),"") | G6: =IFERROR(E6*D6-F6,0) -> 0
A7: 2 | D7: =IFERROR(VLOOKUP(C7, 'Daily Sales Summary Report'!$B$6:$C$47, 2, FALSE),"") | G7: =IFERROR(E7*D7-F7,0) -> 0
A8: 3 | D8: =IFERROR(VLOOKUP(C8, 'Daily Sales Summary Report'!$B$6:$C$47, 2, FALSE),"") | G8: =IFERROR(E8*D8-F8,0) -> 0
A9: 4 | D9: =IFERROR(VLOOKUP(C9, 'Daily Sales Summary Report'!$B$6:$C$47, 2, FALSE),"") | G9: =IFERROR(E9*D9-F9,0) -> 0
A10: 5 | D10: =IFERROR(VLOOKUP(C10, 'Daily Sales Summary Report'!$B$6:$C$47, 2, FALSE),"") | G10: =IFERROR(E10*D10-F10,0) -> 0
A11: 6 | D11: =IFERROR(VLOOKUP(C11, 'Daily Sales Summary Report'!$B$6:$C$47, 2, FALSE),"") | G11: =IFERROR(E11*D11-F11,0) -> 0
A12: 7 | D12: =IFERROR(VLOOKUP(C12, 'Daily Sales Summary Report'!$B$6:$C$47, 2, FALSE),"") | G12: =IFERROR(E12*D12-F12,0) -> 0
A13: 8 | D13: =IFERROR(VLOOKUP(C13, 'Daily Sales Summary Report'!$B$6:$C$47, 2, FALSE),"") | G13: =IFERROR(E13*D13-F13,0) -> 0
A14: 9 | D14: =IFERROR(VLOOKUP(C14, 'Daily Sales Summary Report'!$B$6:$C$47, 2, FALSE),"") | G14: =IFERROR(E14*D14-F14,0) -> 0
A15: 10 | D15: =IFERROR(VLOOKUP(C15, 'Daily Sales Summary Report'!$B$6:$C$47, 2, FALSE),"") | G15: =IFERROR(E15*D15-F15,0) -> 0
A16: 11 | D16: =IFERROR(VLOOKUP(C16, 'Daily Sales Summary Report'!$B$6:$C$47, 2, FALSE),"") | G16: =IFERROR(E16*D16-F16,0) -> 0
A17: 12 | D17: =IFERROR(VLOOKUP(C17, 'Daily Sales Summary Report'!$B$6:$C$47, 2, FALSE),"") | G17: =IFERROR(E17*D17-F17,0) -> 0
... A204: 199 | D204: =IFERROR(VLOOKUP(C204, 'Daily Sales Summary Report'!$B$6:$C$47, 2, FALSE),"") | G204: =IFERROR(E204*D204-F204,0) -> 0
A205: TOTAL | F205: =SUM(F6:F204) -> 0 | G205: =SUM(G6:G204) -> 0

Sheet Daily Sales Summary Report
B1: LIVING
B3: SALES SUMMARY REPORT | J3: MONTH | K3: 45750
A5: S/N | B5: Product Name | C5: Selling Price (Ghs) edit prohibited | D5: Opening Stock Balance (edit prohibited) | E5: Stock Received In (in qty) | F5: Total stock available for sale (in qty) edit prohibited | G5: Stock Transfered Out (in qty) | H5: Currrent Day Sale (in qty) | I5: Discount Allowed (in value) approvals required | J5: Total Value of Sale (Ghs) edit prohibited | K5: Closing Stock Balance (edit prohibited) | L5: NOTES (indicate recipient, location, and waybill number for stock transfers out)
A6: 1 | B6: PRODUCT 1 | C6: 1 | D6: 100 | E6: 20 | F6: =E6+D6 -> 120 | G6: 40 | H6: {=SUMPRODUCT((TRIM('Detailed Sales Report'!C$6:C$204) = B6) * 'Detailed Sales Report'!E$6:E$204)} -> 0 | I6: =SUMIF('Detailed Sales Report'!$C$18:$C$38,'Daily Sales Summary Report'!B6,'Detailed Sales Report'!$F$18:$F$38) -> 0 | J6: =SUMIF('Detailed Sales Report'!$C$18:$C$38,'Daily Sales Summary Report'!B6,'Detailed Sales Report'!$G$18:$G$38) -> 0 | K6: =F6-H6 -> 120
A7: 2 | B7: PRODUCT 2 | C7: 1 | D7: 100 | E7: 20 | F7: =E7+D7 -> 120 | G7: 40 | H7: {=SUMPRODUCT((TRIM('Detailed Sales Report'!C$6:C$204) = B7) * 'Detailed Sales Report'!E$6:E$204)} -> 0 | I7: =SUMIF('Detailed Sales Report'!$C$18:$C$38,'Daily Sales Summary Report'!B7,'Detailed Sales Report'!$F$18:$F$38) -> 0 | J7: =SUMIF('Detailed Sales Report'!$C$18:$C$38,'Daily Sales Summary Report'!B7,'Detailed Sales Report'!$G$18:$G$38) -> 0 | K7: =F7-H7 -> 120
A8: 3 | B8: PRODUCT 3 | C8: 1 | D8: 100 | E8: 20 | F8: =E8+D8 -> 120 | G8: 40 | H8: {=SUMPRODUCT((TRIM('Detailed Sales Report'!C$6:C$204) = B8) * 'Detailed Sales Report'!E$6:E$204)} -> 0 | I8: =SUMIF('Detailed Sales Report'!$C$18:$C$38,'Daily Sales Summary Report'!B8,'Detailed Sales Report'!$F$18:$F$38) -> 0 | J8: =SUMIF('Detailed Sales Report'!$C$18:$C$38,'Daily Sales Summary Report'!B8,'Detailed Sales Report'!$G$18:$G$38) -> 0 | K8: =F8-H8 -> 120
A9: 4 | B9: PRODUCT 4 | C9: 1 | D9: 100 | E9: 20 | F9: =E9+D9 -> 120 | G9: 40 | H9: {=SUMPRODUCT((TRIM('Detailed Sales Report'!C$6:C$204) = B9) * 'Detailed Sales Report'!E$6:E$204)} -> 0 | I9: =SUMIF('Detailed Sales Report'!$C$18:$C$38,'Daily Sales Summary Report'!B9,'Detailed Sales Report'!$F$18:$F$38) -> 0 | J9: =SUMIF('Detailed Sales Report'!$C$18:$C$38,'Daily Sales Summary Report'!B9,'Detailed Sales Report'!$G$18:$G$38) -> 0 | K9: =F9-H9 -> 120
A10: 5 | B10: PRODUCT 5 | C10: 1 | D10: 100 | E10: 20 | F10: =E10+D10 -> 120 | G10: 40 | H10: {=SUMPRODUCT((TRIM('Detailed Sales Report'!C$6:C$204) = B10) * 'Detailed Sales Report'!E$6:E$204)} -> 0 | I10: =SUMIF('Detailed Sales Report'!$C$18:$C$38,'Daily Sales Summary Report'!B10,'Detailed Sales Report'!$F$18:$F$38) -> 0 | J10: =SUMIF('Detailed Sales Report'!$C$18:$C$38,'Daily Sales Summary Report'!B10,'Detailed Sales Report'!$G$18:$G$38) -> 0 | K10: =F10-H10 -> 120
A11: 6 | B11: PRODUCT 6 | C11: 1 | D11: 100 | E11: 20 | F11: =E11+D11 -> 120 | G11: 40 | H11: {=SUMPRODUCT((TRIM('Detailed Sales Report'!C$6:C$204) = B11) * 'Detailed Sales Report'!E$6:E$204)} -> 0 | I11: =SUMIF('Detailed Sales Report'!$C$18:$C$38,'Daily Sales Summary Report'!B11,'Detailed Sales Report'!$F$18:$F$38) -> 0 | J11: =SUMIF('Detailed Sales Report'!$C$18:$C$38,'Daily Sales Summary Report'!B11,'Detailed Sales Report'!$G$18:$G$38) -> 0 | K11: =F11-H11 -> 120
A12: 7 | B12: PRODUCT 7 | C12: 1 | D12: 100 | E12: 20 | F12: =E12+D12 -> 120 | G12: 40 | H12: {=SUMPRODUCT((TRIM('Detailed Sales Report'!C$6:C$204) = B12) * 'Detailed Sales Report'!E$6:E$204)} -> 0 | I12: =SUMIF('Detailed Sales Report'!$C$18:$C$38,'Daily Sales Summary Report'!B12,'Detailed Sales Report'!$F$18:$F$38) -> 0 | J12: =SUMIF('Detailed Sales Report'!$C$18:$C$38,'Daily Sales Summary Report'!B12,'Detailed Sales Report'!$G$18:$G$38) -> 0 | K12: =F12-H12 -> 120
A13: 9 | B13: PRODUCT 8 | C13: 1 | D13: 100 | E13: 20 | F13: =E13+D13 -> 120 | G13: 40 | H13: {=SUMPRODUCT((TRIM('Detailed Sales Report'!C$6:C$204) = B13) * 'Detailed Sales Report'!E$6:E$204)} -> 0 | I13: =SUMIF('Detailed Sales Report'!$C$18:$C$38,'Daily Sales Summary Report'!B13,'Detailed Sales Report'!$F$18:$F$38) -> 0 | J13: =SUMIF('Detailed Sales Report'!$C$18:$C$38,'Daily Sales Summary Report'!B13,'Detailed Sales Report'!$G$18:$G$38) -> 0 | K13: =F13-H13 -> 120
A14: 10 | B14: PRODUCT 9 | C14: 1 | D14: 100 | E14: 20 | F14: =E14+D14 -> 120 | G14: 40 | H14: {=SUMPRODUCT((TRIM('Detailed Sales Report'!C$6:C$204) = B14) * 'Detailed Sales Report'!E$6:E$204)} -> 0 | I14: =SUMIF('Detailed Sales Report'!$C$18:$C$38,'Daily Sales Summary Report'!B14,'Detailed Sales Report'!$F$18:$F$38) -> 0 | J14: =SUMIF('Detailed Sales Report'!$C$18:$C$38,'Daily Sales Summary Report'!B14,'Detailed Sales Report'!$G$18:$G$38) -> 0 | K14: =F14-H14 -> 120
A15: 11 | B15: PRODUCT 10 | C15: 1 | D15: 100 | E15: 20 | F15: =E15+D15 -> 120 | G15: 40 | H15: {=SUMPRODUCT((TRIM('Detailed Sales Report'!C$6:C$204) = B15) * 'Detailed Sales Report'!E$6:E$204)} -> 0 | I15: =SUMIF('Detailed Sales Report'!$C$18:$C$38,'Daily Sales Summary Report'!B15,'Detailed Sales Report'!$F$18:$F$38) -> 0 | J15: =SUMIF('Detailed Sales Report'!$C$18:$C$38,'Daily Sales Summary Report'!B15,'Detailed Sales Report'!$G$18:$G$38) -> 0 | K15: =F15-H15 -> 120
A16: 12 | B16: PRODUCT 11 | C16: 1 | D16: 100 | E16: 20 | F16: =E16+D16 -> 120 | G16: 40 | H16: {=SUMPRODUCT((TRIM('Detailed Sales Report'!C$6:C$204) = B16) * 'Detailed Sales Report'!E$6:E$204)} -> 0 | I16: =SUMIF('Detailed Sales Report'!$C$18:$C$38,'Daily Sales Summary Report'!B16,'Detailed Sales Report'!$F$18:$F$38) -> 0 | J16: =SUMIF('Detailed Sales Report'!$C$18:$C$38,'Daily Sales Summary Report'!B16,'Detailed Sales Report'!$G$18:$G$38) -> 0 | K16: =F16-H16 -> 120
A17: 13 | B17: PRODUCT 12 | C17: 1 | D17: 100 | E17: 20 | F17: =E17+D17 -> 120 | G17: 40 | H17: {=SUMPRODUCT((TRIM('Detailed Sales Report'!C$6:C$204) = B17) * 'Detailed Sales Report'!E$6:E$204)} -> 0 | I17: =SUMIF('Detailed Sales Report'!$C$18:$C$38,'Daily Sales Summary Report'!B17,'Detailed Sales Report'!$F$18:$F$38) -> 0 | J17: =SUMIF('Detailed Sales Report'!$C$18:$C$38,'Daily Sales Summary Report'!B17,'Detailed Sales Report'!$G$18:$G$38) -> 0 | K17: =F17-H17 -> 120
... A25: 21 | B25: PRODUCT 20 | C25: 1 | D25: 100 | E25: 20 | F25: =E25+D25 -> 120 | G25: 40 | H25: {=SUMPRODUCT((TRIM('Detailed Sales Report'!C$6:C$204) = B25) * 'Detailed Sales Report'!E$6:E$204)} -> 0 | I25: =SUMIF('Detailed Sales Report'!$C$18:$C$38,'Daily Sales Summary Report'!B25,'Detailed Sales Report'!$F$18:$F$38) -> 0 | J25: =SUMIF('Detailed Sales Report'!$C$18:$C$38,'Daily Sales Summary Report'!B25,'Detailed Sales Report'!$G$18:$G$38) -> 0 | K25: =F25-H25 -> 120
A26: 22 | C26: 1 | F26: =E26+D26 -> 0 | G26: 40 | H26: {=SUMPRODUCT((TRIM('Detailed Sales Report'!C$6:C$204) = B26) * 'Detailed Sales Report'!E$6:E$204)} -> 0 | I26: =SUMIF('Detailed Sales Report'!$C$18:$C$38,'Daily Sales Summary Report'!B26,'Detailed Sales Report'!$F$18:$F$38) -> 0 | J26: =SUMIF('Detailed Sales Report'!$C$18:$C$38,'Daily Sales Summary Report'!B26,'Detailed Sales Report'!$G$18:$G$38) -> 0 | K26: =F26-H26 -> 0
A27: 22 | F27: =E27+D27 -> 0 | H27: {=SUMPRODUCT((TRIM('Detailed Sales Report'!C$6:C$204) = B27) * 'Detailed Sales Report'!E$6:E$204)} -> 0 | I27: =SUMIF('Detailed Sales Report'!$C$18:$C$38,'Daily Sales Summary Report'!B27,'Detailed Sales Report'!$F$18:$F$38) -> 0 | J27: =SUMIF('Detailed Sales Report'!$C$18:$C$38,'Daily Sales Summary Report'!B27,'Detailed Sales Report'!$G$18:$G$38) -> 0 | K27: =F27-H27 -> 0
A28: 23 | F28: =E28+D28 -> 0 | H28: {=SUMPRODUCT((TRIM('Detailed Sales Report'!C$6:C$204) = B28) * 'Detailed Sales Report'!E$6:E$204)} -> 0 | I28: =SUMIF('Detailed Sales Report'!$C$18:$C$38,'Daily Sales Summary Report'!B28,'Detailed Sales Report'!$F$18:$F$38) -> 0 | J28: =SUMIF('Detailed Sales Report'!$C$18:$C$38,'Daily Sales Summary Report'!B28,'Detailed Sales Report'!$G$18:$G$38) -> 0 | K28: =F28-H28 -> 0
A29: 24 | F29: =E29+D29 -> 0 | H29: {=SUMPRODUCT((TRIM('Detailed Sales Report'!C$6:C$204) = B29) * 'Detailed Sales Report'!E$6:E$204)} -> 0 | I29: =SUMIF('Detailed Sales Report'!$C$18:$C$38,'Daily Sales Summary Report'!B29,'Detailed Sales Report'!$F$18:$F$38) -> 0 | J29: =SUMIF('Detailed Sales Report'!$C$18:$C$38,'Daily Sales Summary Report'!B29,'Detailed Sales Report'!$G$18:$G$38) -> 0 | K29: =F29-H29 -> 0
A30: 25 | D30: 0 | F30: =E30+D30 -> 0 | H30: {=SUMPRODUCT((TRIM('Detailed Sales Report'!C$6:C$204) = B30) * 'Detailed Sales Report'!E$6:E$204)} -> 0 | I30: =SUMIF('Detailed Sales Report'!$C$18:$C$38,'Daily Sales Summary Report'!B30,'Detailed Sales Report'!$F$18:$F$38) -> 0 | J30: =SUMIF('Detailed Sales Report'!$C$18:$C$38,'Daily Sales Summary Report'!B30,'Detailed Sales Report'!$G$18:$G$38) -> 0 | K30: =F30-H30 -> 0
A31: 26 | F31: =E31+D31 -> 0 | H31: {=SUMPRODUCT((TRIM('Detailed Sales Report'!C$6:C$204) = B31) * 'Detailed Sales Report'!E$6:E$204)} -> 0 | I31: =SUMIF('Detailed Sales Report'!$C$18:$C$38,'Daily Sales Summary Report'!B31,'Detailed Sales Report'!$F$18:$F$38) -> 0 | J31: =SUMIF('Detailed Sales Report'!$C$18:$C$38,'Daily Sales Summary Report'!B31,'Detailed Sales Report'!$G$18:$G$38) -> 0 | K31: =F31-H31 -> 0
A32: 27 | F32: =E32+D32 -> 0 | H32: {=SUMPRODUCT((TRIM('Detailed Sales Report'!C$6:C$204) = B32) * 'Detailed Sales Report'!E$6:E$204)} -> 0 | I32: =SUMIF('Detailed Sales Report'!$C$18:$C$38,'Daily Sales Summary Report'!B32,'Detailed Sales Report'!$F$18:$F$38) -> 0 | J32: =SUMIF('Detailed Sales Report'!$C$18:$C$38,'Daily Sales Summary Report'!B32,'Detailed Sales Report'!$G$18:$G$38) -> 0 | K32: =F32-H32 -> 0
A33: 28 | D33: 0 | H33: {=SUMPRODUCT((TRIM('Detailed Sales Report'!C$6:C$204) = B33) * 'Detailed Sales Report'!E$6:E$204)} -> 0 | I33: =SUMIF('Detailed Sales Report'!$C$18:$C$38,'Daily Sales Summary Report'!B33,'Detailed Sales Report'!$F$18:$F$38) -> 0 | J33: =SUMIF('Detailed Sales Report'!$C$18:$C$38,'Daily Sales Summary Report'!B33,'Detailed Sales Report'!$G$18:$G$38) -> 0 | K33: =F33-H33 -> 0
A34: 29 | F34: =E34+D34 -> 0 | H34: {=SUMPRODUCT((TRIM('Detailed Sales Report'!C$6:C$204) = B34) * 'Detailed Sales Report'!E$6:E$204)} -> 0 | I34: =SUMIF('Detailed Sales Report'!$C$18:$C$38,'Daily Sales Summary Report'!B34,'Detailed Sales Report'!$F$18:$F$38) -> 0 | J34: =SUMIF('Detailed Sales Report'!$C$18:$C$38,'Daily Sales Summary Report'!B34,'Detailed Sales Report'!$G$18:$G$38) -> 0 | K34: =F34-H34 -> 0
A35: 30 | F35: =E35+D35 -> 0 | H35: {=SUMPRODUCT((TRIM('Detailed Sales Report'!C$6:C$204) = B35) * 'Detailed Sales Report'!E$6:E$204)} -> 0 | I35: =SUMIF('Detailed Sales Report'!$C$18:$C$38,'Daily Sales Summary Report'!B35,'Detailed Sales Report'!$F$18:$F$38) -> 0 | J35: =SUMIF('Detailed Sales Report'!$C$18:$C$38,'Daily Sales Summary Report'!B35,'Detailed Sales Report'!$G$18:$G$38) -> 0 | K35: =F35-H35 -> 0
A36: 31 | F36: =E36+D36 -> 0 | H36: {=SUMPRODUCT((TRIM('Detailed Sales Report'!C$6:C$204) = B36) * 'Detailed Sales Report'!E$6:E$204)} -> 0 | I36: =SUMIF('Detailed Sales Report'!$C$18:$C$38,'Daily Sales Summary Report'!B36,'Detailed Sales Report'!$F$18:$F$38) -> 0 | J36: =SUMIF('Detailed Sales Report'!$C$18:$C$38,'Daily Sales Summary Report'!B36,'Detailed Sales Report'!$G$18:$G$38) -> 0 | K36: =F36-H36 -> 0
A37: 32 | F37: =E37+D37 -> 0 | H37: {=SUMPRODUCT((TRIM('Detailed Sales Report'!C$6:C$204) = B37) * 'Detailed Sales Report'!E$6:E$204)} -> 0 | I37: =SUMIF('Detailed Sales Report'!$C$18:$C$38,'Daily Sales Summary Report'!B37,'Detailed Sales Report'!$F$18:$F$38) -> 0 | J37: =SUMIF('Detailed Sales Report'!$C$18:$C$38,'Daily Sales Summary Report'!B37,'Detailed Sales Report'!$G$18:$G$38) -> 0 | K37: =F37-H37 -> 0
A38: 33 | F38: =E38+D38 -> 0 | H38: {=SUMPRODUCT((TRIM('Detailed Sales Report'!C$6:C$204) = B38) * 'Detailed Sales Report'!E$6:E$204)} -> 0 | I38: =SUMIF('Detailed Sales Report'!$C$18:$C$38,'Daily Sales Summary Report'!B38,'Detailed Sales Report'!$F$18:$F$38) -> 0 | J38: =SUMIF('Detailed Sales Report'!$C$18:$C$38,'Daily Sales Summary Report'!B38,'Detailed Sales Report'!$G$18:$G$38) -> 0 | K38: =F38-H38 -> 0
A39: 34 | F39: =E39+D39 -> 0 | H39: {=SUMPRODUCT((TRIM('Detailed Sales Report'!C$6:C$204) = B39) * 'Detailed Sales Report'!E$6:E$204)} -> 0 | I39: =SUMIF('Detailed Sales Report'!$C$18:$C$38,'Daily Sales Summary Report'!B39,'Detailed Sales Report'!$F$18:$F$38) -> 0 | J39: =SUMIF('Detailed Sales Report'!$C$18:$C$38,'Daily Sales Summary Report'!B39,'Detailed Sales Report'!$G$18:$G$38) -> 0 | K39: =F39-H39 -> 0
A40: 35 | F40: =E40+D40 -> 0 | H40: {=SUMPRODUCT((TRIM('Detailed Sales Report'!C$6:C$204) = B40) * 'Detailed Sales Report'!E$6:E$204)} -> 0 | I40: =SUMIF('Detailed Sales Report'!$C$18:$C$38,'Daily Sales Summary Report'!B40,'Detailed Sales Report'!$F$18:$F$38) -> 0 | J40: =SUMIF('Detailed Sales Report'!$C$18:$C$38,'Daily Sales Summary Report'!B40,'Detailed Sales Report'!$G$18:$G$38) -> 0 | K40: =F40-H40 -> 0
A41: 36 | F41: =E41+D41 -> 0 | H41: {=SUMPRODUCT((TRIM('Detailed Sales Report'!C$6:C$204) = B41) * 'Detailed Sales Report'!E$6:E$204)} -> 0 | I41: =SUMIF('Detailed Sales Report'!$C$18:$C$38,'Daily Sales Summary Report'!B41,'Detailed Sales Report'!$F$18:$F$38) -> 0 | J41: =SUMIF('Detailed Sales Report'!$C$18:$C$38,'Daily Sales Summary Report'!B41,'Detailed Sales Report'!$G$18:$G$38) -> 0 | K41: =F41-H41 -> 0
A42: 37 | F42: =E42+D42 -> 0 | H42: {=SUMPRODUCT((TRIM('Detailed Sales Report'!C$6:C$204) = B42) * 'Detailed Sales Report'!E$6:E$204)} -> 0 | I42: =SUMIF('Detailed Sales Report'!$C$18:$C$38,'Daily Sales Summary Report'!B42,'Detailed Sales Report'!$F$18:$F$38) -> 0 | J42: =SUMIF('Detailed Sales Report'!$C$18:$C$38,'Daily Sales Summary Report'!B42,'Detailed Sales Report'!$G$18:$G$38) -> 0 | K42: =F42-H42 -> 0
A43: 38 | E43: 0 | F43: =E43+D43 -> 0 | H43: {=SUMPRODUCT((TRIM('Detailed Sales Report'!C$6:C$204) = B43) * 'Detailed Sales Report'!E$6:E$204)} -> 0 | I43: =SUMIF('Detailed Sales Report'!$C$18:$C$38,'Daily Sales Summary Report'!B43,'Detailed Sales Report'!$F$18:$F$38) -> 0 | J43: =SUMIF('Detailed Sales Report'!$C$18:$C$38,'Daily Sales Summary Report'!B43,'Detailed Sales Report'!$G$18:$G$38) -> 0 | K43: =F43-H43 -> 0
A44: 39 | F44: =E44+D44 -> 0 | H44: {=SUMPRODUCT((TRIM('Detailed Sales Report'!C$6:C$204) = B44) * 'Detailed Sales Report'!E$6:E$204)} -> 0 | I44: =SUMIF('Detailed Sales Report'!$C$18:$C$38,'Daily Sales Summary Report'!B44,'Detailed Sales Report'!$F$18:$F$38) -> 0 | J44: =SUMIF('Detailed Sales Report'!$C$18:$C$38,'Daily Sales Summary Report'!B44,'Detailed Sales Report'!$G$18:$G$38) -> 0 | K44: =F44-H44 -> 0
A45: 40 | F45: =E45+D45 -> 0 | H45: {=SUMPRODUCT((TRIM('Detailed Sales Report'!C$6:C$204) = B45) * 'Detailed Sales Report'!E$6:E$204)} -> 0 | I45: =SUMIF('Detailed Sales Report'!$C$18:$C$38,'Daily Sales Summary Report'!B45,'Detailed Sales Report'!$F$18:$F$38) -> 0 | J45: =SUMIF('Detailed Sales Report'!$C$18:$C$38,'Daily Sales Summary Report'!B45,'Detailed Sales Report'!$G$18:$G$38) -> 0 | K45: =F45-H45 -> 0
A46: 41 | D46: 0 | F46: =E46+D46 -> 0 | H46: {=SUMPRODUCT((TRIM('Detailed Sales Report'!C$6:C$204) = B46) * 'Detailed Sales Report'!E$6:E$204)} -> 0 | I46: =SUMIF('Detailed Sales Report'!$C$18:$C$38,'Daily Sales Summary Report'!B46,'Detailed Sales Report'!$F$18:$F$38) -> 0 | J46: =SUMIF('Detailed Sales Report'!$C$18:$C$38,'Daily Sales Summary Report'!B46,'Detailed Sales Report'!$G$18:$G$38) -> 0 | K46: =F46-H46 -> 0
A47: 42 | H47: {=SUMPRODUCT((TRIM('Detailed Sales Report'!C$6:C$204) = B47) * 'Detailed Sales Report'!E$6:E$204)} -> 0 | I47: =SUMIF('Detailed Sales Report'!$C$18:$C$38,'Daily Sales Summary Report'!B47,'Detailed Sales Report'!$F$18:$F$38) -> 0 | J47: =SUMIF('Detailed Sales Report'!$C$18:$C$38,'Daily Sales Summary Report'!B47,'Detailed Sales Report'!$G$18:$G$38) -> 0 | K47: =F47-H47 -> 0
C48: TOTAL (edit prohibited) | I48: =SUM(I6:I47) -> 0 | J48: =SUMIF('Detailed Sales Report'!$C$18:$C$38,'Daily Sales Summary Report'!B48,'Detailed Sales Report'!$G$18:$G$38) -> 0 | K48: =F48-H48 -> 0
B49: REPORT PREPARED BY: | K49: =F49-H49 -> 0
...
